{"name": "test_login_invalid_credentials", "status": "broken", "statusDetails": {"message": "TypeError: APIClient.post() got an unexpected keyword argument 'data'", "trace": "api_context = <playwright._impl._fetch.APIRequestContext object at 0x000001F299204830>\n\n    @pytest.mark.api\n    def test_login_invalid_credentials(api_context):\n        login_api = LoginAPI(api_context)\n>       response = login_api.login(\n            username=\"invaliduser\",\n            password=\"wrongpass\",\n            expiresInMins=30\n        )\n\ntest_login.py:28: \n_ _ _ _ _ _ _ _ _ _ _ _ _ _ _ _ _ _ _ _ _ _ _ _ _ _ _ _ _ _ _ _ _ _ _ _ _ _ _ _ _ _ _ _ _ _ _ _ _ _ _ _ _ _ _ _ _ _ _ _ _ _ _ _ _ _ _ _ _ _ _ _ _ _ _ _ _ _ _ _ _\n\nself = <api.users_api.LoginAPI object at 0x000001F29916E0D0>, username = 'invaliduser', password = 'wrongpass', expiresInMins = 30\n\n    def login(self, username: str, password: str, expiresInMins: int = 60):\n        payload = {\n            \"username\": username,\n            \"password\": password,\n            \"expiresInMins\": expiresInMins\n        }\n>       return self.post(self.base_endpoint, data=payload)\n               ^^^^^^^^^^^^^^^^^^^^^^^^^^^^^^^^^^^^^^^^^^^\nE       TypeError: APIClient.post() got an unexpected keyword argument 'data'\n\n..\\api\\users_api.py:22: TypeError"}, "start": 1758626834016, "stop": 1758626834016, "uuid": "7ce05916-0112-4d9d-8294-6795699a571b", "historyId": "ba4e553d88338b4c3aa782986d363389", "testCaseId": "ba4e553d88338b4c3aa782986d363389", "fullName": "tests.test_login#test_login_invalid_credentials", "labels": [{"name": "tag", "value": "api"}, {"name": "parentSuite", "value": "tests"}, {"name": "suite", "value": "test_login"}, {"name": "host", "value": "PC-2993"}, {"name": "thread", "value": "20836-MainThread"}, {"name": "framework", "value": "pytest"}, {"name": "language", "value": "cpython3"}, {"name": "package", "value": "tests.test_login"}], "titlePath": ["tests", "test_login.py"]}